Workbook

Sheet Hoja1
A1: CEDI | B1: CLIENTE | C1: VOLUMEN | D1: VISIBILIDAD | E1: TOTAL
A2: CARLOS PROAÑO | B2: ANDRADE ANDRADE GEMA LUCIA | C2: 0 | D2: 0 | E2: 0
A3: CARLOS PROAÑO | B3: ARBOLEDA VACA LETTY VIRGINIA | C3: 2770.1334 | D3: 750 | E3: 3520.1334
A4: CARLOS PROAÑO | B4: AVEIGA FALCONES DANY MARON | C4: 721.35231 | D4: 510 | E4: 1231.3523
A5: CARLOS PROAÑO | B5: BRAVO CEDEÑO NELSON RENE | C5: 518.96954 | D5: 0 | E5: 518.96954
A6: CARLOS PROAÑO | B6: CEDEÑO MEDINA WASHINGTON MONSERRATE | C6: 223.79758 | D6: 180 | E6: 403.79758
A7: CARLOS PROAÑO | B7: COMERCIAL CASANOVA COMCASANOVA S.A. | C7: 2019.5665 | D7: 510 | E7: 2529.5665
A8: CARLOS PROAÑO | B8: COMERCIAL ROMERO REYNA COMRO | C8: 480.51276 | D8: 150 | E8: 630.51276
A9: CARLOS PROAÑO | B9: COMERCIALIZADORA BASURTO & SACON SUPERUNO S.A. | C9: 1185.8746 | D9: 150 | E9: 1335.8746
A10: CARLOS PROAÑO | B10: GLORIA DEL CARMEN FALLU VERA | C10: 425.66414 | D10: 0 | E10: 425.66414
A11: CARLOS PROAÑO | B11: MACIAS CEDEÑO CESAR ENRIQUE | C11: 1633.3839 | D11: 150 | E11: 1783.3839
A12: CARLOS PROAÑO | B12: MARIA NOHELIA MUÑOZ GILER | C12: 1347.544 | D12: 150 | E12: 1497.544
A13: CARLOS PROAÑO | B13: PALMA CEDEÑO WALTER ALEJANDRO | C13: 0 | D13: 120 | E13: 120
... A63: XAVIER ALVARADO | B63: YANEZ CARDENAS ESTELA ELIZABET | C63: 345.19111 | D63: 120 | E63: 465.19111

Sheet Hoja2
A3: Etiquetas de fila | B3: Suma de Suma de REBATE REAL VOL
A4: Total general

Sheet PRESUPUESTO VISIBILIDAD UTILIZA
A3: Etiquetas de fila | B3: Suma de CABECERA5 | C3: Suma de ISLA5 | D3: Suma de PERCHA5 | E3: TOTAL | G3: =56000/4 -> 14000
A4: CARLOS PROAÑO | B4: 1890 | C4: 960 | D4: 1660 | E4: =SUM(B4:D4) -> 4510
A5: GEOVANNY CANCHINGRE | B5: 140 | C5: 885 | D5: 600 | E5: =SUM(B5:D5) -> 1625
A6: MARCELO ESPINOZA | B6: 720 | C6: 1800 | D6: 360 | E6: =SUM(B6:D6) -> 2880
A7: XAVIER ALVARADO | B7: 1680 | C7: 930 | D7: 660 | E7: =SUM(B7:D7) -> 3270
A8: Total general | B8: 4430 | C8: 4575 | D8: 3280 | E8: =SUM(B8:D8) -> 12285
A11: Q1
A12: CEDI | B12: VOLUMEN | C12: VISIBILIDAD | D12: TOTAL | E12: PROVISION VISIBILIDAD
A13: Total CARLOS PROAÑO | B13: 12006.546 | C13: 4510 | D13: =+B13+C13 -> 16516.546
A14: Total GEOVANNY CANCHINGRE | B14: 1383.0757 | C14: 1625 | D14: =+B14+C14 -> 3008.0757
A15: Total MARCELO ESPINOZA | B15: 19823.706 | C15: 2880 | D15: =+B15+C15 -> 22703.706
A16: Total XAVIER ALVARADO | B16: 6367.5257 | C16: 3270 | D16: =+B16+C16 -> 9637.5257
A17: Total general | B17: 39580.854 | C17: 12285 | D17: =+B17+C17 -> 51865.854 | E17: 13250 | F17: =+C17/E17 -> 0.92716981
A20: PRESUPUESTO VOLUMEN POR Q | B20: 49443
A22: CEDI | B22: 2026 | C22: Q1 | D22: Q2 | E22: Q3 | F22: Q4
A23: GUAYAQUIL | B23: $ 10.830,00 | C23: $ 2.707,50 | D23: $ 2.707,50 | E23: $ 2.707,50 | F23: $ 2.707,50
A24: MANABÍ | B24: $ 15.390,00 | C24: $ 3.847,50 | D24: $ 3.847,50 | E24: $ 3.847,50 | F24: $ 3.847,50
A25: QUITO | B25: $ 16.530,00 | C25: $ 4.132,50 | D25: $ 4.132,50 | E25: $ 4.132,50 | F25: $ 4.132,50
A26: SANTO DOMINGO | B26: $ 14.250,00 | C26: $ 3.562,50 | D26: $ 3.562,50 | E26: $ 3.562,50 | F26: $ 3.562,50
A27: Total general | B27: $ 57.000,00 | C27: $ 14.250,00 | D27: $14.250,00 | E27: $14.250,00 | F27: $14.250,00
A30: Q2
A32: Etiquetas de fila | B32: Suma de VOLUMEN | C32: Suma de VISIBILIDAD
A33: CARLOS PROAÑO | B33: 14450.247 | C33: 4980 | D33: PRESUPUESTO PASADO
A34: JAVIER MALDONADO | B34: 2541.1351 | C34: 1485
A35: MARCELO ESPINOZA | B35: 17159.143 | C35: 3150
A36: XAVIER ALVARADO | B36: 6007.2815 | C36: 3090 | D36: PRESUPUESTO PASADO
A37: Total general | B37: 40157.806 | C37: 12705
A41: AGENCIA | B41: VOLUMEN | C41: VISIBILIDAD | E41: AGENCIA | F41: Q3 VISIBILIDAD | G41: Q4 VISIBILIDAD
A42: CARLOS PROAÑO | B42: 14450.247 | C42: 4980 | E42: CARLOS PROAÑO | F42: 2715 | G42: 3847.5 | H42: =+C42-G42 -> 1132.5
A43: JAVIER MALDONADO | B43: 2541.1351 | C43: 1485 | E43: JAVIER MALDONADO | F43: 4132.5 | G43: 4132.5 | H43: =+C43-G43 -> -2647.5
A44: MARCELO ESPINOZA | B44: 17159.143 | C44: 3150 | E44: MARCELO ESPINOZA | F44: 3562.5 | G44: 3562.5 | H44: =+C44-G44 -> -412.5
A45: XAVIER ALVARADO | B45: 6007.2815 | C45: 3090 | E45: XAVIER ALVARADO | F45: 2325 | G45: 2707.5 | H45: =+C45-G45 -> 382.5 | I45: =+G45-H45 -> 2325
A46: TOTAL | B46: =SUM(B42:B45) -> 40157.806 | C46: =SUM(C42:C45) -> 12705
A49: Q3 | E49: CEDI | F49: VISIBILIDAD
E50: CARLOS PROAÑO | F50: 4510
E51: JAVIER MALDONADO | F51: 1625
E52: MARCELO ESPINOZA | F52: 2880
E53: XAVIER ALVARADO | F53: 3270
E54: Total general | F54: 12285

Sheet RESUMEN DE PAGOS
A3: CEDI | B3: CLIENTE | C3: VOLUMEN | D3: VISIBILIDAD | E3: TOTAL
A4: CARLOS PROAÑO | B4: ANDRADE ANDRADE GEMA LUCIA | C4: 0 | D4: 0 | E4: =+C4+D4 -> 0
A5: CARLOS PROAÑO | B5: ARBOLEDA VACA LETTY VIRGINIA | C5: 2613.5796 | D5: =VLOOKUP(B5,'VISIBILIDAD '!$C$3:$U$45,19,FALSE) -> 750 | E5: =+C5+D5 -> 3363.5796
A6: CARLOS PROAÑO | B6: AVEIGA FALCONES DANY MARON | C6: 862.40548 | D6: =VLOOKUP(B6,'VISIBILIDAD '!$C$3:$U$45,19,FALSE) -> 540 | E6: =+C6+D6 -> 1402.4055
A7: CARLOS PROAÑO | B7: BRAVO CEDEÑO NELSON RENE | C7: 737.81022 | D7: 0 | E7: =+C7+D7 -> 737.81022
A8: CARLOS PROAÑO | B8: CEDEÑO MEDINA WASHINGTON MONSERRATE | C8: 262.77763 | D8: =VLOOKUP(B8,'VISIBILIDAD '!$C$3:$U$45,19,FALSE) -> 150 | E8: =+C8+D8 -> 412.77763
A9: CARLOS PROAÑO | B9: COMERCIAL CASANOVA COMCASANOVA S.A. | C9: 2338.1996 | D9: =VLOOKUP(B9,'VISIBILIDAD '!$C$3:$U$45,19,FALSE) -> 510 | E9: =+C9+D9 -> 2848.1996
A10: CARLOS PROAÑO | B10: COMERCIAL ROMERO REYNA COMRO | C10: 0 | D10: =VLOOKUP(B10,'VISIBILIDAD '!$C$3:$U$45,19,FALSE) -> 0 | E10: =+C10+D10 -> 0
A11: CARLOS PROAÑO | B11: COMERCIALIZADORA BASURTO & SACON SUPERUNO S.A. | C11: 0 | D11: =VLOOKUP(B11,'VISIBILIDAD '!$C$3:$U$45,19,FALSE) -> 300 | E11: =+C11+D11 -> 300
A12: CARLOS PROAÑO | B12: GILER ZAMBRANO MARIA PAOLA | C12: 1458.6192 | D12: 330 | E12: =+C12+D12 -> 1788.6192
A13: CARLOS PROAÑO | B13: GLORIA DEL CARMEN FALLU VERA | C13: 480.55512 | D13: 0 | E13: =+C13+D13 -> 480.55512
A14: CARLOS PROAÑO | B14: MACIAS CEDEÑO CESAR ENRIQUE | C14: 1932.7478 | D14: 1050 | E14: =+C14+D14 -> 2982.7478
A15: CARLOS PROAÑO | B15: PALMA CEDEÑO WALTER ALEJANDRO | C15: 940.10966 | D15: =VLOOKUP(B15,'VISIBILIDAD '!$C$3:$U$45,19,FALSE) -> 360 | E15: =+C15+D15 -> 1300.1097
A16: CARLOS PROAÑO | B16: PIGUAVE BELLO CATTY | C16: 278.63875 | D16: =VLOOKUP(B16,'VISIBILIDAD '!$C$3:$U$45,19,FALSE) -> 0 | E16: =+C16+D16 -> 278.63875
A17: CARLOS PROAÑO | B17: ROBERT - PONCE COMPANY S.A.S | C17: 0 | D17: 0 | E17: =+C17+D17 -> 0
A18: CARLOS PROAÑO | B18: URETA MENDOZA ERMEL RUBEN | C18: 0 | D18: 0 | E18: =+C18+D18 -> 0
A19: CARLOS PROAÑO | B19: URETA MENDOZA YIMMY ANTONIO | C19: 793.79266 | D19: =VLOOKUP(B19,'VISIBILIDAD '!$C$3:$U$45,19,FALSE) -> 510 | E19: =+C19+D19 -> 1303.7927
A20: CARLOS PROAÑO | B20: WANG CHONG LONG | C20: 0 | D20: 0 | E20: =+C20+D20 -> 0
A21: CARLOS PROAÑO | B21: ZAMBRANO MACIAS FRANCISCO GREGORIO | C21: 983.01886 | D21: =VLOOKUP(B21,'VISIBILIDAD '!$C$3:$U$45,19,FALSE) -> 150 | E21: =+C21+D21 -> 1133.0189
A22: CARLOS PROAÑO | B22: ZAMBRANO MOLINA JORGE EDUARDO | C22: 347.63944 | D22: =VLOOKUP(B22,'VISIBILIDAD '!$C$3:$U$45,19,FALSE) -> 330 | E22: =+C22+D22 -> 677.63944
A23: CARLOS PROAÑO | B23: ZAMBRANO VALENCIA MARGARITA | C23: 0 | D23: =VLOOKUP(B23,'VISIBILIDAD '!$C$3:$U$45,19,FALSE) -> 0 | E23: =+C23+D23 -> 0
A24: CARLOS PROAÑO | B24: ZAMBRANO ZAMBRANO CLEYTON ELIECER | C24: 420.35263 | D24: 0 | E24: =+C24+D24 -> 420.35263
A25: Total CARLOS PROAÑO | C25: 14450.247 | D25: =SUM(D4:D24) -> 4980 | E25: =+C25+D25 -> 19430.247
A26: JAVIER MALDONADO | B26: BUSTAMANTE RAMIRO OSWALDO | C26: 0 | D26: =VLOOKUP(B26,'VISIBILIDAD '!$C$3:$U$45,19,FALSE) -> 450 | E26: =+C26+D26 -> 450
A27: JAVIER MALDONADO | B27: COMISARIATO ELSITIO C.L. | C27: 371.6453 | D27: 270 | E27: =+C27+D27 -> 641.6453
A28: JAVIER MALDONADO | B28: DISTRIBUIDORA SUPERALIANZA S.A.S | C28: 183.79488 | D28: 405 | E28: =+C28+D28 -> 588.79488
A29: JAVIER MALDONADO | B29: GUADALUPE CASTILLO ERNESTO VICENTE | C29: 1146.288 | D29: 0 | E29: =+C29+D29 -> 1146.288
A30: JAVIER MALDONADO | B30: MASTIAN CHILENO LUIS GEOVANNY | C30: 572.748 | D30: 0 | E30: =+C30+D30 -> 572.748
A31: JAVIER MALDONADO | B31: YUCAILLA PADILLA RENE WILFRIDO | C31: 266.65895 | D31: =VLOOKUP(B31,'VISIBILIDAD '!$C$3:$U$45,19,FALSE) -> 360 | E31: =+C31+D31 -> 626.65895
A32: Total JAVIER MALDONADO | C32: 2354.1505 | D32: =SUM(D26:D31) -> 1485 | E32: =+C32+D32 -> 3839.1505
A33: MARCELO ESPINOZA | B33: BRAVO MORETA DORIS VANESSA (SUPER DESPENSA POLITA) | C33: 983.31902 | D33: 270 | E33: =+C33+D33 -> 1253.319
A34: MARCELO ESPINOZA | B34: CAIVEL S.A. | C34: 2900.7595 | D34: =VLOOKUP(B34,'VISIBILIDAD '!$C$3:$U$45,19,FALSE) -> 120 | E34: =+C34+D34 -> 3020.7595
A35: MARCELO ESPINOZA | B35: CEDEPLUS S.C.C. | C35: 2301.4708 | D35: 330 | E35: =+C35+D35 -> 2631.4708
A36: MARCELO ESPINOZA | B36: COMERCIAL LA FERIA HLS CIA.LTDA. | C36: 7890.9679 | D36: =VLOOKUP(B36,'VISIBILIDAD '!$C$3:$U$45,19,FALSE) -> 120 | E36: =+C36+D36 -> 8010.9679
A37: MARCELO ESPINOZA | B37: DISTRIBUIDORA SUPER TIENDA QUEVEDO LUMACAI SA | C37: 0 | D37: =VLOOKUP(B37,'VISIBILIDAD '!$C$3:$U$45,19,FALSE) -> 120 | E37: =+C37+D37 -> 120
A38: MARCELO ESPINOZA | B38: GALLARDO BUSTILLOS GENESIS ESTEFANIA | C38: 0 | D38: =VLOOKUP(B38,'VISIBILIDAD '!$C$3:$U$45,19,FALSE) -> 480 | E38: =+C38+D38 -> 480
A39: MARCELO ESPINOZA | B39: HERRERA CABRERA JENNY JACQUELINE | C39: 909.30626 | D39: =VLOOKUP(B39,'VISIBILIDAD '!$C$3:$U$45,19,FALSE) -> 360 | E39: =+C39+D39 -> 1269.3063
A40: MARCELO ESPINOZA | B40: IMPORTADORA CARANQUI CIA.LTDA. | C40: 0 | D40: 120 | E40: =+C40+D40 -> 120
A41: MARCELO ESPINOZA | B41: LITARDO MURILLO JANELA ALEXANDRA | C41: 301.57264 | D41: =VLOOKUP(B41,'VISIBILIDAD '!$C$3:$U$45,19,FALSE) -> 0 | E41: =+C41+D41 -> 301.57264
A42: MARCELO ESPINOZA | B42: LOMBEIDA GONZALEZ JENNY SILVANA | C42: 0 | D42: =VLOOKUP(B42,'VISIBILIDAD '!$C$3:$U$45,19,FALSE) -> 120 | E42: =+C42+D42 -> 120
...

Sheet VISIBILIDAD 
A1: NO BORRAR - BI | E1: CANTIDAD | H1: PAGO | L1: MARCA | O1: VALIDACIÓN
A2: KP | B2: CEDI | C2: Nombres | D2: PLAN | E2: CABECERA | F2: ISLA | G2: PERCHA | H2: CABECERA | I2: ISLA | J2: PERCHA | K2: PAGO TOTAL | L2: CABECERA | M2: ISLA | N2: PERCHA | O2: CABECERA | P2: ISLA | Q2: PERCHA | R2: CABECERA | S2: ISLA | T2: PERCHA | U2: TOTAL | V2: OBSERVACION
A3: =CONCATENATE(C3,#REF!) -> #REF! | B3: XAVIER ALVARADO | C3: MORAN LOPEZ WILMER ALFREDO | D3: AUTOSERVICIO INDEPENDIENTE | E3: 1 | F3: 1 | G3: 0 | H3: 360 | I3: 90 | J3: =G3*180 -> 0 | K3: =+H3+I3+J3 -> 450 | L3: MULTIMARCA | M3: LIQUIDOS | O3: CUMPLE | P3: CUMPLE | Q3: NO CUMPLE | R3: =+IF(O3="CUMPLE",H3,0) -> 360 | S3: =+IF(P3="CUMPLE",I3,0) -> 90 | T3: =+IF(Q3="CUMPLE",J3,0) -> 0 | U3: =+SUM(R3:T3) -> 450
B4: XAVIER ALVARADO | C4: DISTRIBUIDORA DE PRODUCTOS DE CONSUMO MASIVO CODIPROMASA C.A | D4: AUTOSERVICIO INDEPENDIENTE | E4: 0 | F4: 2 | G4: 0 | H4: =E4*240 -> 0 | I4: =F4*120 -> 240 | J4: =+G4*120 -> 0 | K4: =+H4+I4+J4 -> 240 | M4: MULTIMARCA | O4: NO CUMPLE | P4: CUMPLE | Q4: NO CUMPLE | R4: =+IF(O4="CUMPLE",H4,0) -> 0 | S4: =+IF(P4="CUMPLE",I4,0) -> 240 | T4: =+IF(Q4="CUMPLE",J4,0) -> 0 | U4: =+SUM(R4:T4) -> 240
A5: =CONCATENATE(C5,#REF!) -> #REF! | B5: XAVIER ALVARADO | C5: DISPROYSER S.A. | D5: AUTOSERVICIO INDEPENDIENTE | E5: 2 | F5: 0 | G5: 0 | H5: 720 | I5: =F5*90 -> 0 | J5: =G5*180 -> 0 | K5: =+H5+I5+J5 -> 720 | L5: LAVA - GOL | O5: CUMPLE | P5: NO CUMPLE | Q5: NO CUMPLE | R5: =+IF(O5="CUMPLE",H5,0) -> 720 | S5: =+IF(P5="CUMPLE",I5,0) -> 0 | T5: =+IF(Q5="CUMPLE",J5,0) -> 0 | U5: =+SUM(R5:T5) -> 720
A6: =CONCATENATE(C6,#REF!) -> #REF! | B6: XAVIER ALVARADO | C6: ROXANA VILLACIS S.A. ROXVILL | D6: AUTOSERVICIO INDEPENDIENTE | E6: 1 | F6: 0 | G6: 0 | H6: =E6*150 -> 150 | I6: 0 | J6: 0 | K6: =+H6+I6+J6 -> 150 | L6: LAVA | O6: CUMPLE | P6: NO CUMPLE | Q6: NO CUMPLE | R6: =+IF(O6="CUMPLE",H6,0) -> 150 | S6: =+IF(P6="CUMPLE",I6,0) -> 0 | T6: =+IF(Q6="CUMPLE",J6,0) -> 0 | U6: =+SUM(R6:T6) -> 150
B7: XAVIER ALVARADO | C7: ORTEGA GONZALEZ HERMES ADALBER | D7: AUTOSERVICIO INDEPENDIENTE | E7: 0 | F7: 0 | G7: 1 | H7: =E7*150 -> 0 | I7: =+F7*120 -> 0 | J7: 150 | K7: =+H7+I7+J7 -> 150 | N7: PERCHA MIX | O7: NO CUMPLE | P7: NO CUMPLE | Q7: CUMPLE | R7: =+IF(O7="CUMPLE",H7,0) -> 0 | S7: =+IF(P7="CUMPLE",I7,0) -> 0 | T7: =+IF(Q7="CUMPLE",J7,0) -> 150 | U7: =+SUM(R7:T7) -> 150
A8: =CONCATENATE(C8,#REF!) -> #REF! | B8: XAVIER ALVARADO | C8: CAYA-AUTOSERVICIOS S.A.S | D8: AUTOSERVICIO INDEPENDIENTE | E8: 1 | F8: 0 | G8: 2 | H8: =E8*150 -> 150 | I8: =F8*75 -> 0 | J8: =G8*120 -> 240 | K8: =+H8+I8+J8 -> 390 | L8: MULTIMARCA | N8: GOL-LAVA | O8: CUMPLE | P8: NO CUMPLE | Q8: CUMPLE | R8: =+IF(O8="CUMPLE",H8,0) -> 150 | S8: =+IF(P8="CUMPLE",I8,0) -> 0 | T8: =+IF(Q8="CUMPLE",J8,0) -> 240 | U8: =+SUM(R8:T8) -> 390
A9: =CONCATENATE(C9,#REF!) -> #REF! | B9: CARLOS PROAÑO | C9: PIGUAVE BELLO CATTY | D9: AUTOSERVICIO INDEPENDIENTE | G9: 1 | H9: =E9*240 -> 0 | I9: =F9*120 -> 0 | J9: =G9*150 -> 150 | K9: =+H9+I9+J9 -> 150 | N9: LAVA | O9: NO CUMPLE | P9: NO CUMPLE | Q9: NO CUMPLE | R9: =+IF(O9="CUMPLE",H9,0) -> 0 | S9: =+IF(P9="CUMPLE",I9,0) -> 0 | T9: =+IF(Q9="CUMPLE",J9,0) -> 0 | U9: =+SUM(R9:T9) -> 0
A10: =CONCATENATE(C10,#REF!) -> #REF! | B10: CARLOS PROAÑO | C10: ZAMBRANO MOLINA JORGE EDUARDO | D10: AUTOSERVICIO INDEPENDIENTE | E10: 0 | F10: 1 | G10: 1 | H10: =E10*240 -> 0 | I10: 180 | J10: 150 | K10: =+H10+I10+J10 -> 330 | M10: LIQUIDOS | N10: LAVA | O10: NO CUMPLE | P10: CUMPLE | Q10: CUMPLE | R10: =+IF(O10="CUMPLE",H10,0) -> 0 | S10: =+IF(P10="CUMPLE",I10,0) -> 180 | T10: =+IF(Q10="CUMPLE",J10,0) -> 150 | U10: =+SUM(R10:T10) -> 330
A11: =CONCATENATE(C11,#REF!) -> #REF! | B11: CARLOS PROAÑO | C11: ARBOLEDA VACA LETTY VIRGINIA | D11: AUTOSERVICIO INDEPENDIENTE | E11: 1 | F11: 0 | G11: 1 | H11: =E11*600 -> 600 | I11: =F11*120 -> 0 | J11: 150 | K11: =+H11+I11+J11 -> 750 | L11: GOL | N11: LAVA | O11: CUMPLE | P11: NO CUMPLE | Q11: CUMPLE | R11: =+IF(O11="CUMPLE",H11,0) -> 600 | S11: =+IF(P11="CUMPLE",I11,0) -> 0 | T11: =+IF(Q11="CUMPLE",J11,0) -> 150 | U11: =+SUM(R11:T11) -> 750
A12: =CONCATENATE(C12,#REF!) -> #REF! | B12: CARLOS PROAÑO | C12: COMERCIAL CASANOVA COMCASANOVA S.A. | D12: AUTOSERVICIO INDEPENDIENTE | E12: 1 | F12: 0 | G12: 1 | H12: =E12*360 -> 360 | I12: =F12*120 -> 0 | J12: 150 | K12: =+H12+I12+J12 -> 510 | L12: GOL | N12: LAVA | O12: CUMPLE | P12: NO CUMPLE | Q12: CUMPLE | R12: =+IF(O12="CUMPLE",H12,0) -> 360 | S12: =+IF(P12="CUMPLE",I12,0) -> 0 | T12: =+IF(Q12="CUMPLE",J12,0) -> 150 | U12: =+SUM(R12:T12) -> 510
A13: =CONCATENATE(C13,#REF!) -> #REF! | B13: CARLOS PROAÑO | C13: COMERCIALIZADORA BASURTO & SACON SUPERUNO S.A. | D13: AUTOSERVICIO INDEPENDIENTE | E13: 0 | F13: 0 | G13: 2 | H13: =E13*240 -> 0 | I13: =F13*120 -> 0 | J13: 300 | K13: =+H13+I13+J13 -> 300 | N13: LAVA -GOL | O13: NO CUMPLE | P13: NO CUMPLE | Q13: CUMPLE | R13: =+IF(O13="CUMPLE",H13,0) -> 0 | S13: =+IF(P13="CUMPLE",I13,0) -> 0 | T13: =+IF(Q13="CUMPLE",J13,0) -> 300 | U13: =+SUM(R13:T13) -> 300
A14: =CONCATENATE(C14,#REF!) -> #REF! | B14: CARLOS PROAÑO | C14: URETA MENDOZA YIMMY ANTONIO | D14: AUTOSERVICIO INDEPENDIENTE | E14: 0 | F14: 2 | G14: 1 | H14: =E14*240 -> 0 | I14: 360 | J14: 150 | K14: =+H14+I14+J14 -> 510 | M14: GOL - LIQUIDOS | N14: LAVA | O14: NO CUMPLE | P14: CUMPLE | Q14: CUMPLE | R14: =+IF(O14="CUMPLE",H14,0) -> 0 | S14: =+IF(P14="CUMPLE",I14,0) -> 360 | T14: =+IF(Q14="CUMPLE",J14,0) -> 150 | U14: =+SUM(R14:T14) -> 510
A15: =CONCATENATE(C15,#REF!) -> #REF! | B15: CARLOS PROAÑO | C15: PALMA CEDEÑO WALTER ALEJANDRO | D15: AUTOSERVICIO INDEPENDIENTE | E15: 0 | F15: 2 | G15: 0 | H15: =E15*240 -> 0 | I15: 360 | K15: =+H15+I15+J15 -> 360 | M15: GOL-LIQUIDOS | O15: NO CUMPLE | P15: CUMPLE | Q15: NO CUMPLE | R15: =+IF(O15="CUMPLE",H15,0) -> 0 | S15: =+IF(P15="CUMPLE",I15,0) -> 360 | T15: =+IF(Q15="CUMPLE",J15,0) -> 0 | U15: =+SUM(R15:T15) -> 360
A16: =CONCATENATE(C16,#REF!) -> #REF! | B16: CARLOS PROAÑO | C16: ZAMBRANO MACIAS FRANCISCO GREGORIO | D16: AUTOSERVICIO INDEPENDIENTE | G16: 1 | H16: =E16*240 -> 0 | I16: =F16*120 -> 0 | J16: 150 | K16: =+H16+I16+J16 -> 150 | N16: LAVA | O16: NO CUMPLE | P16: NO CUMPLE | Q16: CUMPLE | R16: =+IF(O16="CUMPLE",H16,0) -> 0 | S16: =+IF(P16="CUMPLE",I16,0) -> 0 | T16: =+IF(Q16="CUMPLE",J16,0) -> 150 | U16: =+SUM(R16:T16) -> 150
B17: CARLOS PROAÑO | C17: MACIAS CEDEÑO CESAR ENRIQUE/MACIAS CEDEÑO LUIS FERNANDO | D17: AUTOSERVICIO INDEPENDIENTE | E17: 2 | F17: 0 | G17: 1 | H17: 900 | I17: =F17*120 -> 0 | J17: 150 | K17: =+H17+I17+J17 -> 1050 | L17: LAVA-GOL | N17: LAVA | O17: CUMPLE | P17: NO CUMPLE | Q17: CUMPLE | R17: =+IF(O17="CUMPLE",H17,0) -> 900 | S17: =+IF(P17="CUMPLE",I17,0) -> 0 | T17: =+IF(Q17="CUMPLE",J17,0) -> 150 | U17: =+SUM(R17:T17) -> 1050
A18: =CONCATENATE(C18,#REF!) -> #REF! | B18: CARLOS PROAÑO | C18: ZAMBRANO VALENCIA MARGARITA | D18: AUTOSERVICIO INDEPENDIENTE | E18: 0 | F18: 1 | G18: 1 | H18: =E18*240 -> 0 | I18: 180 | J18: 150 | K18: =+H18+I18+J18 -> 330 | M18: GOL | N18: LAVA | O18: NO CUMPLE | P18: NO CUMPLE | Q18: NO CUMPLE | R18: =+IF(O18="CUMPLE",H18,0) -> 0 | S18: =+IF(P18="CUMPLE",I18,0) -> 0 | T18: =+IF(Q18="CUMPLE",J18,0) -> 0 | U18: =+SUM(R18:T18) -> 0 | V18: NO CUMPLIO ISLA EN MAYO NO CUMPLIO PERCHA NUMERO DE CARAS
A19: =CONCATENATE(C19,#REF!) -> #REF! | B19: CARLOS PROAÑO | C19: AVEIGA FALCONES DANY MARON | D19: AUTOSERVICIO INDEPENDIENTE | E19: 1 | F19: 2 | H19: 180 | I19: 360 | J19: 0 | K19: =+H19+I19+J19 -> 540 | L19: LAVA | M19: GOL-LIQUIDOS | O19: CUMPLE | P19: CUMPLE | Q19: NO CUMPLE | R19: =+IF(O19="CUMPLE",H19,0) -> 180 | S19: =+IF(P19="CUMPLE",I19,0) -> 360 | T19: =+IF(Q19="CUMPLE",J19,0) -> 0 | U19: =+SUM(R19:T19) -> 540
B20: CARLOS PROAÑO | C20: GILER ZAMBRANO MARIA PAOLA | D20: AUTOSERVICIO INDEPENDIENTE | E20: 1 | G20: 1 | H20: 180 | I20: 0 | J20: 150 | K20: =+H20+I20+J20 -> 330 | L20: LAVA | N20: LAVA | O20: CUMPLE | P20: NO CUMPLE | Q20: CUMPLE | R20: =+IF(O20="CUMPLE",H20,0) -> 180 | S20: =+IF(P20="CUMPLE",I20,0) -> 0 | T20: =+IF(Q20="CUMPLE",J20,0) -> 150 | U20: =+SUM(R20:T20) -> 330
A21: =CONCATENATE(C21,#REF!) -> #REF! | B21: CARLOS PROAÑO | C21: COMERCIAL ROMERO REYNA COMRO | D21: AUTOSERVICIO INDEPENDIENTE | G21: 1 | H21: =E21*240 -> 0 | I21: =F21*120 -> 0 | J21: =G21*150 -> 150 | K21: =+H21+I21+J21 -> 150 | N21: LAVA | O21: NO CUMPLE | P21: NO CUMPLE | Q21: NO CUMPLE | R21: =+IF(O21="CUMPLE",H21,0) -> 0 | S21: =+IF(P21="CUMPLE",I21,0) -> 0 | T21: =+IF(Q21="CUMPLE",J21,0) -> 0 | U21: =+SUM(R21:T21) -> 0 | V21: NO CUMPLE NUMERO DE CARAS EN PERCHA
A22: =CONCATENATE(C22,#REF!) -> #REF! | B22: CARLOS PROAÑO | C22: CEDEÑO MEDINA WASHINGTON MONSERRATE | D22: AUTOSERVICIO INDEPENDIENTE | E22: 1 | F22: 0 | G22: 0 | H22: 150 | I22: =F22*120 -> 0 | J22: =G22*200 -> 0 | K22: =+H22+I22+J22 -> 150 | L22: MULTIMARCA | O22: CUMPLE | P22: NO CUMPLE | Q22: NO CUMPLE | R22: =+IF(O22="CUMPLE",H22,0) -> 150 | S22: =+IF(P22="CUMPLE",I22,0) -> 0 | T22: =+IF(Q22="CUMPLE",J22,0) -> 0 | U22: =+SUM(R22:T22) -> 150
A23: =CONCATENATE(C23,#REF!) -> #REF! | B23: MARCELO ESPINOZA | C23: PINCAY PALACIOS YOCONDA ANALIA (IMPORTADORA CARANQUI CIA . LTDA) | D23: AUTOSERVICIO INDEPENDIENTE | E23: 0 | F23: 1 | G23: 1 | H23: =E23*240 -> 0 | I23: =F23*120 -> 120 | J23: 150 | K23: =+H23+I23+J23 -> 270 | M23: GOL | N23: LAVA | O23: NO CUMPLE | P23: CUMPLE | Q23: NO CUMPLE | R23: =+IF(O23="CUMPLE",H23,0) -> 0 | S23: =+IF(P23="CUMPLE",I23,0) -> 120 | T23: =+IF(Q23="CUMPLE",J23,0) -> 0 | U23: =+SUM(R23:T23) -> 120 | V23: NO CUMPLE NUMERO DE CARAS EN PERCHA
B24: MARCELO ESPINOZA | C24: GALLARDO BUSTILLOS GENESIS ESTEFANIA | D24: AUTOSERVICIO INDEPENDIENTE | E24: 0 | F24: 1 | G24: 2 | H24: 0 | I24: 180 | J24: 300 | K24: =+H24+I24+J24 -> 480 | M24: GOL | N24: LAVA-GOL | O24: CUMPLE | P24: CUMPLE | Q24: CUMPLE | R24: =+IF(O24="CUMPLE",H24,0) -> 0 | S24: =+IF(P24="CUMPLE",I24,0) -> 180 | T24: =+IF(Q24="CUMPLE",J24,0) -> 300 | U24: =+SUM(R24:T24) -> 480
A25: =CONCATENATE(C25,#REF!) -> #REF! | B25: MARCELO ESPINOZA | C25: BRAVO MORETA DORIS VANESSA (SUPER DESPENSA POLITA) | D25: AUTOSERVICIO INDEPENDIENTE | F25: 1 | G25: 1 | H25: =E25*240 -> 0 | I25: =F25*120 -> 120 | J25: 150 | K25: =+H25+I25+J25 -> 270 | M25: GOL | N25: LAVA | O25: NO CUMPLE | P25: CUMPLE | Q25: CUMPLE | R25: =+IF(O25="CUMPLE",H25,0) -> 0 | S25: =+IF(P25="CUMPLE",I25,0) -> 120 | T25: =+IF(Q25="CUMPLE",J25,0) -> 150 | U25: =+SUM(R25:T25) -> 270
A26: =CONCATENATE(C26,#REF!) -> #REF! | B26: MARCELO ESPINOZA | C26: COMERCIAL LA FERIA HLS CIA.LTDA. | D26: AUTOSERVICIO INDEPENDIENTE | E26: 0 | F26: 2 | G26: 1 | H26: =E26*240 -> 0 | I26: =F26*120 -> 240 | J26: 150 | K26: =+H26+I26+J26 -> 390 | M26: GOL-LAVA | N26: LAVA | O26: NO CUMPLE | P26: CUMPLE | Q26: NO CUMPLE | R26: =+IF(O26="CUMPLE",H26,0) -> 0 | S26: =+IF(P26="CUMPLE",I26,0)/2 -> 120 | T26: =+IF(Q26="CUMPLE",J26,0) -> 0 | U26: =+SUM(R26:T26) -> 120 | V26: NO CUMPLE NUMERO DE CARAS EN PERCHA/NO CUMPLE CON LA ISLA LAVA
B27: MARCELO ESPINOZA | C27: QUICHIMBO DIAZ CENELIA DEL CISNE | D27: AUTOSERVICIO INDEPENDIENTE | E27: 1 | F27: 2 | G27: 1 | H27: 180 | I27: =F27*120 -> 240 | J27: 150 | K27: =H27+I27+J27 -> 570 | L27: LAVA | M27: GOL-LAVA | N27: LAVA | O27: CUMPLE | P27: CUMPLE | Q27: NO CUMPLE | R27: =+IF(O27="CUMPLE",H27,0) -> 180 | S27: =+IF(P27="CUMPLE",I27,0) -> 240 | T27: =+IF(Q27="CUMPLE",J27,0) -> 0 | U27: =+SUM(R27:T27) -> 420
B28: MARCELO ESPINOZA | C28: SOCIEDAD CIVIL MARCSOL Y CIA | D28: AUTOSERVICIO INDEPENDIENTE | E28: 0 | F28: 1 | G28: 2 | H28: =E28*240 -> 0 | I28: 180 | J28: 300 | K28: =+H28+I28+J28 -> 480 | M28: GOL | N28: LAVA-GOL | O28: NO CUMPLE | P28: CUMPLE | Q28: NO CUMPLE | R28: =+IF(O28="CUMPLE",H28,0) -> 0 | S28: =+IF(P28="CUMPLE",I28,0) -> 180 | T28: =+IF(Q28="CUMPLE",J28,0) -> 0 | U28: =+SUM(R28:T28) -> 180 | V28: NO CUMPLE NUMERO DE CARAS
B29: MARCELO ESPINOZA | C29: CAIVEL S.A. | D29: AUTOSERVICIO INDEPENDIENTE | E29: 0 | F29: 1 | G29: 1 | H29: =E29*240 -> 0 | I29: =F29*120 -> 120 | J29: 150 | K29: =+H29+I29+J29 -> 270 | M29: GOL | N29: LAVA | O29: NO CUMPLE | P29: CUMPLE | Q29: NO CUMPLE | R29: =+IF(O29="CUMPLE",H29,0) -> 0 | S29: =+IF(P29="CUMPLE",I29,0) -> 120 | T29: =+IF(Q29="CUMPLE",J29,0) -> 0 | U29: =+SUM(R29:T29) -> 120 | V29: NO CUMPLE NUMERO DE CARAS
B30: MARCELO ESPINOZA | C30: CEDEÑO INTRIAGO FABIAN VICENTE/CEDEPLUSS SCC | D30: AUTOSERVICIO INDEPENDIENTE | E30: 0 | F30: 1 | G30: 2 | H30: 0 | I30: 180 | J30: 300 | K30: =+H30+I30+J30 -> 480 | M30: GOL | N30: LAVA-GOL | O30: NO CUMPLE | P30: CUMPLE | Q30: CUMPLE | R30: =+IF(O30="CUMPLE",H30,0) -> 0 | S30: =+IF(P30="CUMPLE",I30,0) -> 180 | T30: =+IF(Q30="CUMPLE",J30,0)/2 -> 150 | U30: =+SUM(R30:T30) -> 330 | V30: NO CUMPLE CON EL NUMERO DE CARAS DE LA PERCHA LAVA
B31: MARCELO ESPINOZA | C31: SAMANIEGO TANDAZO BLADIMIR FELIX (SUPER SAV) | D31: AUTOSERVICIO INDEPENDIENTE | E31: 0 | F31: 2 | G31: 1 | H31: =E31*240 -> 0 | I31: 240 | J31: =G31*180 -> 180 | K31: =+H31+I31+J31 -> 420 | M31: LAVA-GOL | N31: LAVA | O31: NO CUMPLE | P31: CUMPLE | Q31: NO CUMPLE | R31: =+IF(O31="CUMPLE",H31,0) -> 0 | S31: =+IF(P31="CUMPLE",I31,0) -> 240 | T31: =+IF(Q31="CUMPLE",J31,0) -> 0 | U31: =+SUM(R31:T31) -> 240 | V31: NO CUMPLE NUMERO DE CARAS LAVA
B32: MARCELO ESPINOZA | C32: ROSERO AGUILAR LUIS BAYARDO | D32: AUTOSERVICIO INDEPENDIENTE | E32: 0 | F32: 0 | G32: 1 | H32: =E32*240 -> 0 | I32: 0 | J32: 150 | K32: =+H32+I32+J32 -> 150 | N32: LAVA | O32: NO CUMPLE | P32: NO CUMPLE | Q32: CUMPLE | R32: =+IF(O32="CUMPLE",H32,0) -> 0 | S32: =+IF(P32="CUMPLE",I32,0) -> 0 | T32: =+IF(Q32="CUMPLE",J32,0) -> 150 | U32: =+SUM(R32:T32) -> 150
B33: MARCELO ESPINOZA | C33: LITARDO MURILLO JANELA ALEXANDRA | D33: AUTOSERVICIO INDEPENDIENTE | E33: 0 | F33: 1 | G33: 1 | H33: =E33*240 -> 0 | I33: =F33*120 -> 120 | J33: 150 | K33: =+H33+I33+J33 -> 270 | M33: GOL | N33: GOL | O33: NO CUMPLE | P33: NO CUMPLE | Q33: NO CUMPLE | R33: =+IF(O33="CUMPLE",H33,0) -> 0 | S33: =+IF(P33="CUMPLE",I33,0) -> 0 | T33: =+IF(Q33="CUMPLE",J33,0) -> 0 | U33: =+SUM(R33:T33) -> 0 | V33: NO CUMPLE NUMERO DE CARAS/NO TIENE ISLA EN EL MES ABRIL SEMANA 3 DE MAYO -JUNIO
B34: MARCELO ESPINOZA | C34: DISTRIBUIDORA SUPER TIENDA QUEVEDO LUMACAI SA | D34: AUTOSERVICIO INDEPENDIENTE | E34: 0 | F34: 1 | G34: 1 | H34: =E34*240 -> 0 | I34: =F34*120 -> 120 | J34: 150 | K34: =+H34+I34+J34 -> 270 | M34: GOL | N34: LAVA | O34: NO CUMPLE | P34: CUMPLE | Q34: NO CUMPLE | R34: =+IF(O34="CUMPLE",H34,0) -> 0 | S34: =+IF(P34="CUMPLE",I34,0) -> 120 | T34: =+IF(Q34="CUMPLE",J34,0) -> 0 | U34: =+SUM(R34:T34) -> 120 | V34: NO CUMPLE NUMERO DE CARAS EN LAVA
B35: MARCELO ESPINOZA | C35: LOMBEIDA GONZALEZ WILSON BAYARDO(COMISARIATO LA GRAN OFERTA) | D35: AUTOSERVICIO INDEPENDIENTE | F35: 1 | G35: 1 | H35: =E35*240 -> 0 | I35: =F35*120 -> 120 | J35: 150 | K35: =+H35+I35+J35 -> 270 | M35: GOL | N35: LAVA | O35: NO CUMPLE | P35: CUMPLE | Q35: NO CUMPLE | R35: =+IF(O35="CUMPLE",H35,0) -> 0 | S35: =+IF(P35="CUMPLE",I35,0) -> 120 | T35: =+IF(Q35="CUMPLE",J35,0) -> 0 | U35: =+SUM(R35:T35) -> 120 | V35: NO CUMPLE NUMERO DE CARAS EN LAVA
B36: MARCELO ESPINOZA | C36: LOMBEIDA GONZALEZ JENNY SILVANA | D36: AUTOSERVICIO INDEPENDIENTE | E36: 0 | F36: 1 | G36: 1 | H36: =E36*240 -> 0 | I36: =F36*120 -> 120 | J36: 150 | K36: =+H36+I36+J36 -> 270 | M36: GOL | N36: LAVA | O36: NO CUMPLE | P36: CUMPLE | Q36: NO CUMPLE | R36: =+IF(O36="CUMPLE",H36,0) -> 0 | S36: =+IF(P36="CUMPLE",I36,0) -> 120 | T36: =+IF(Q36="CUMPLE",J36,0) -> 0 | U36: =+SUM(R36:T36) -> 120 | V36: NO CUMPLE NUMERO DE CARAS EN LAVA
B37: MARCELO ESPINOZA | C37: HERRERA CABRERA JENNY JACQUELINE | D37: AUTOSERVICIO INDEPENDIENTE | E37: 1 | F37: 1 | G37: 0 | H37: 180 | I37: 180 | J37: =G37*180 -> 0 | K37: =+H37+I37+J37 -> 360 | L37: LAVA | M37: GOL | O37: CUMPLE | P37: CUMPLE | Q37: NO CUMPLE | R37: =+IF(O37="CUMPLE",H37,0) -> 180 | S37: =+IF(P37="CUMPLE",I37,0) -> 180 | T37: =+IF(Q37="CUMPLE",J37,0) -> 0 | U37: =+SUM(R37:T37) -> 360 | V37: NO CUMPLE NUMERO DE CARAS EN LAVA
B38: XAVIER ALVARADO | C38: YANEZ CARDENAS ESTELA ELIZABET | D38: MAYORISTA PURO | E38: 1 | F38: 0 | G38: 0 | H38: 120 | I38: 0 | J38: 0 | K38: =+H38+I38+J38 -> 120 | L38: EXHIBIDOR MULTIMARCA | O38: CUMPLE | P38: NO CUMPLE | Q38: NO CUMPLE | R38: =+IF(O38="CUMPLE",H38,0) -> 120 | S38: =+IF(P38="CUMPLE",I38,0) -> 0 | T38: =+IF(Q38="CUMPLE",J38,0) -> 0 | U38: =+SUM(R38:T38) -> 120
B39: XAVIER ALVARADO | C39: ALMANE CIA. LTDA. | D39: AUTOSERVICIO INDEPENDIENTE | E39: 1 | F39: 1 | G39: 1 | H39: =+E39*240 -> 240 | I39: 60 | J39: =+G39*180 -> 180 | K39: =+H39+I39+J39 -> 480 | L39: LAVA | M39: LIQUIDOS | N39: BARRA | O39: CUMPLE | P39: CUMPLE | Q39: CUMPLE | R39: =+IF(O39="CUMPLE",H39,0) -> 240 | S39: =+IF(P39="CUMPLE",I39,0) -> 60 | T39: =+IF(Q39="CUMPLE",J39,0) -> 180 | U39: =+SUM(R39:T39) -> 480
B40: XAVIER ALVARADO | C40: MOVACAZA S.A.S | D40: AUTOSERVICIO INDEPENDIENTE | E40: 1 | F40: 0 | G40: 1 | H40: 150 | I40: 0 | J40: 120 | K40: =+H40+I40+J40 -> 270 | L40: GOL | N40: LAVA | O40: CUMPLE | P40: NO CUMPLE | Q40: CUMPLE | R40: =+IF(O40="CUMPLE",H40,0) -> 150 | S40: =+IF(P40="CUMPLE",I40,0) -> 0 | T40: =+IF(Q40="CUMPLE",J40,0) -> 120 | U40: =+SUM(R40:T40) -> 270
...

Sheet CUOTA TOTAL
A3: CEDI | B3: CLIENTE | C3: Suma de TOTAL Q2 | D3: Suma de VENTA Q4
A4: CARLOS PROAÑO | B4: ANDRADE ANDRADE GEMA LUCIA | C4: 21660 | D4: 11331.272 | E4: =+D4/C4 -> 0.52314276 | F4: =IF(E4>=99.99%,"GANA","NO GANA") -> NO GANA
A5: CARLOS PROAÑO | B5: ARBOLEDA VACA LETTY VIRGINIA | C5: 76440 | D5: 76579.693 | E5: =+D5/C5 -> 1.0018275 | F5: =IF(E5>=99.99%,"GANA","NO GANA") -> GANA
A6: CARLOS PROAÑO | B6: AVEIGA FALCONES DANY MARON | C6: 26271 | D6: 26576.874 | E6: =+D6/C6 -> 1.011643 | F6: =IF(E6>=99.99%,"GANA","NO GANA") -> GANA
A7: CARLOS PROAÑO | B7: BRAVO CEDEÑO NELSON RENE | C7: 19194.72 | D7: 21961.516 | E7: =+D7/C7 -> 1.1441436 | F7: =IF(E7>=99.99%,"GANA","NO GANA") -> GANA
A8: CARLOS PROAÑO | B8: CEDEÑO MEDINA WASHINGTON MONSERRATE | C8: 7405.62 | D8: 7519.7296 | E8: =+D8/C8 -> 1.0154085 | F8: =IF(E8>=99.99%,"GANA","NO GANA") -> GANA
A9: CARLOS PROAÑO | B9: COMERCIAL CASANOVA COMCASANOVA S.A. | C9: 62183.82 | D9: 67171.588 | E9: =+D9/C9 -> 1.0802101 | F9: =IF(E9>=99.99%,"GANA","NO GANA") -> GANA
A10: CARLOS PROAÑO | B10: COMERCIAL ROMERO REYNA COMRO | C10: 14796 | D10: 11159.429 | E10: =+D10/C10 -> 0.75421929 | F10: =IF(E10>=99.99%,"GANA","NO GANA") -> NO GANA
A11: CARLOS PROAÑO | B11: COMERCIALIZADORA BASURTO & SACON SUPERUNO S.A. | C11: 62430 | D11: 52873.463 | E11: =+D11/C11 -> 0.84692396 | F11: =IF(E11>=99.99%,"GANA","NO GANA") -> NO GANA
A12: CARLOS PROAÑO | B12: GILER ZAMBRANO MARIA PAOLA | C12: 40393.02 | D12: 41875.202 | E12: =+D12/C12 -> 1.036694 | F12: =IF(E12>=99.99%,"GANA","NO GANA") -> GANA
A13: CARLOS PROAÑO | B13: GLORIA DEL CARMEN FALLU VERA | C13: 13647 | D13: 14187.202 | E13: =+D13/C13 -> 1.039584 | F13: =IF(E13>=99.99%,"GANA","NO GANA") -> GANA
A14: CARLOS PROAÑO | B14: MACIAS CEDEÑO CESAR ENRIQUE | C14: 50531.25 | D14: 64664.598 | E14: =+D14/C14 -> 1.2796952 | F14: =IF(E14>=99.99%,"GANA","NO GANA") -> GANA
A15: CARLOS PROAÑO | B15: PALMA CEDEÑO WALTER ALEJANDRO | C15: 27893.58 | D15: 31746.385 | E15: =+D15/C15 -> 1.1381251 | F15: =IF(E15>=99.99%,"GANA","NO GANA") -> GANA
... A24: CARLOS PROAÑO | B24: ZAMBRANO ZAMBRANO CLEYTON ELIECER | C24: 11052 | D24: 11826.094 | E24: =+D24/C24 -> 1.0700411 | F24: =IF(E24>=99.99%,"GANA","NO GANA") -> GANA
A25: Total CARLOS PROAÑO | C25: 560179.8 | D25: 546537.21 | E25: =+D25/C25 -> 0.97564604 | F25: =IF(E25>=99.99%,"GANA","NO GANA") -> NO GANA
A26: JAVIER MALDONADO | B26: BUSTAMANTE RAMIRO OSWALDO | C26: 9567 | D26: 7170.6182 | E26: =+D26/C26 -> 0.74951586 | F26: =IF(E26>=99.99%,"GANA","NO GANA") -> NO GANA
A27: JAVIER MALDONADO | B27: COMISARIATO ELSITIO C.L. | C27: 40116 | D27: 49367.711 | E27: =+D27/C27 -> 1.230624 | F27: =IF(E27>=99.99%,"GANA","NO GANA") -> GANA
A28: JAVIER MALDONADO | B28: DISTRIBUIDORA SUPERALIANZA S.A.S | C28: 4620 | D28: 5474.8206 | E28: =+D28/C28 -> 1.1850261 | F28: =IF(E28>=99.99%,"GANA","NO GANA") -> GANA
A29: JAVIER MALDONADO | B29: GUADALUPE CASTILLO ERNESTO VICENTE | C29: 30921 | D29: 34448.446 | E29: =+D29/C29 -> 1.1140793 | F29: =IF(E29>=99.99%,"GANA","NO GANA") -> GANA
A30: JAVIER MALDONADO | B30: MASTIAN CHILENO LUIS GEOVANNY | C30: 13782 | D30: 16357.322 | E30: =+D30/C30 -> 1.1868613 | F30: =IF(E30>=99.99%,"GANA","NO GANA") -> GANA
A31: JAVIER MALDONADO | B31: YUCAILLA PADILLA RENE WILFRIDO | C31: 6204 | D31: 7172.6736 | E31: =+D31/C31 -> 1.1561369 | F31: =IF(E31>=99.99%,"GANA","NO GANA") -> GANA
A32: Total JAVIER MALDONADO | C32: 105210 | D32: 119991.59 | E32: =+D32/C32 -> 1.1404961 | F32: =IF(E32>=99.99%,"GANA","NO GANA") -> GANA
A33: MARCELO ESPINOZA | B33: BRAVO MORETA DORIS VANESSA (SUPER DESPENSA POLITA) | C33: 27372.96 | D33: 30580.783 | E33: =+D33/C33 -> 1.1171895 | F33: =IF(E33>=99.99%,"GANA","NO GANA") -> GANA
A34: MARCELO ESPINOZA | B34: CAIVEL S.A. | C34: 72619.2 | D34: 83073.426 | E34: =+D34/C34 -> 1.1439595 | F34: =IF(E34>=99.99%,"GANA","NO GANA") -> GANA
A35: MARCELO ESPINOZA | B35: CEDEPLUS S.C.C. | C35: 65453.28 | D35: 65474.312 | E35: =+D35/C35 -> 1.0003213 | F35: =IF(E35>=99.99%,"GANA","NO GANA") -> GANA
A36: MARCELO ESPINOZA | B36: COMERCIAL LA FERIA HLS CIA.LTDA. | C36: 205030.23 | D36: 232008.82 | E36: =+D36/C36 -> 1.1315835 | F36: =IF(E36>=99.99%,"GANA","NO GANA") -> GANA
A37: MARCELO ESPINOZA | B37: DISTRIBUIDORA SUPER TIENDA QUEVEDO LUMACAI SA | C37: 18410.16 | D37: 7866.9728 | E37: =+D37/C37 -> 0.42731692 | F37: =IF(E37>=99.99%,"GANA","NO GANA") -> NO GANA
A38: MARCELO ESPINOZA | B38: GALLARDO BUSTILLOS GENESIS ESTEFANIA | C38: 54177.48 | D38: 32689.058 | E38: =+D38/C38 -> 0.60336985 | F38: =IF(E38>=99.99%,"GANA","NO GANA") -> NO GANA
A39: MARCELO ESPINOZA | B39: HERRERA CABRERA JENNY JACQUELINE | C39: 23867.61 | D39: 33336.768 | E39: =+D39/C39 -> 1.3967368 | F39: =IF(E39>=99.99%,"GANA","NO GANA") -> GANA
A40: MARCELO ESPINOZA | B40: IMPORTADORA CARANQUI CIA.LTDA. | C40: 14749.68 | D40: 4434.686 | E40: =+D40/C40 -> 0.3006632 | F40: =IF(E40>=99.99%,"GANA","NO GANA") -> NO GANA
A41: MARCELO ESPINOZA | B41: LITARDO MURILLO JANELA ALEXANDRA | C41: 24415.14 | D41: 24456.294 | E41: =+D41/C41 -> 1.0016856 | F41: =IF(E41>=99.99%,"GANA","NO GANA") -> GANA
A42: MARCELO ESPINOZA | B42: LOMBEIDA GONZALEZ JENNY SILVANA | C42: 8119.23 | D42: 2588.4032 | E42: =+D42/C42 -> 0.3187991 | F42: =IF(E42>=99.99%,"GANA","NO GANA") -> NO GANA
A43: MARCELO ESPINOZA | B43: LOMBEIDA GONZALEZ WILSON BAYARDO(COMISARIATO LA GRAN OFERTA) | C43: 31893.78 | D43: 17219.414 | E43: =+D43/C43 -> 0.53989882 | F43: =IF(E43>=99.99%,"GANA","NO GANA") -> NO GANA
A44: MARCELO ESPINOZA | B44: QUICHIMBO DIAZ CENELIA DEL CISNE | C44: 107458.32 | D44: 53783.053 | E44: =+D44/C44 -> 0.50050153 | F44: =IF(E44>=99.99%,"GANA","NO GANA") -> NO GANA
... A47: MARCELO ESPINOZA | B47: SOCIEDAD CIVIL MARCSOL Y CIA | C47: 53520.3 | D47: 56373.853 | E47: =+D47/C47 -> 1.0533172 | F47: =IF(E47>=99.99%,"GANA","NO GANA") -> GANA
A48: Total MARCELO ESPINOZA | C48: 770918.22 | D48: 689746.44 | E48: =+D48/C48 -> 0.89470767 | F48: =IF(E48>=99.99%,"GANA","NO GANA") -> NO GANA
A49: XAVIER ALVARADO | B49: ALMANE CIA. LTDA. | C49: 23463 | D49: 25698.016 | E49: =+D49/C49 -> 1.095257 | F49: =IF(E49>=99.99%,"GANA","NO GANA") -> GANA
A50: XAVIER ALVARADO | B50: ALVARADO ORELLANA YADIRA EVELYN | C50: 24105 | D50: 24272.162 | E50: =+D50/C50 -> 1.0069348 | F50: =IF(E50>=99.99%,"GANA","NO GANA") -> GANA
A51: XAVIER ALVARADO | B51: CARRILLO GALARZA MARCO ANTONIO | C51: 38580 | D51: 0 | E51: =+D51/C51 -> 0 | F51: =IF(E51>=99.99%,"GANA","NO GANA") -> NO GANA
A52: XAVIER ALVARADO | B52: CAYA-AUTOSERVICIOS S.A.S | C52: 20739 | D52: 22149.764 | E52: =+D52/C52 -> 1.0680247 | F52: =IF(E52>=99.99%,"GANA","NO GANA") -> GANA
...

Sheet CUOTA CLIENTE - CATEGORÍA
M1: VENTA Q2 2026
A2: CEDI | B2: CLIENTE | C2: PLAN | D2: CATEGORIAS | E2: CONCAT | F2: ABRIL | G2: MAYO | H2: JUNIO | I2: TOTAL Q2 | J2: REBATE A APLICAR % | K2: REBATE $ | L2: REBATE MAXIMO 110% | M2: ABRIL | N2: MAYO | O2: JUNIO | P2: CARTERA | Q2: VENTA Q2 | R2: CUMPLIMIENTO | S2: GANA POR CATEGORÍA | T2: GANA TOTAL | U2: PRE REBATE | V2: REBATE REAL VOL | Y2: NOVEDADES
A3: CARLOS PROAÑO | B3: ZAMBRANO ZAMBRANO CLEYTON ELIECER | C3: AUTOSERVICIO INDEPENDIENTE | D3: BARRA | E3: =_xlfn.CONCAT(B3,D3) -> ZAMBRANO ZAMBRANO CLEYTON ELIECERBARRA | F3: 600 | G3: 600 | H3: 600 | I3: =+F3+G3+H3 -> 1800 | J3: 0.015 | K3: =+I3*J3 -> 27 | L3: =(I3*1.1)*J3 -> 29.7 | M3: 697.8188 | N3: 213.648 | O3: 673.6268 | P3: 0 | Q3: =SUM(M3:O3) -> 1585.0936 | R3: =+Q3/I3 -> 0.88060756 | S3: =IF(R3>=80%,"GANA","NO GANA") -> GANA | T3: =VLOOKUP(B3,'CUOTA TOTAL'!$B$4:$F$72,5,FALSE) -> GANA | U3: =IF(AND(T3="GANA",S3="GANA"),Q3*J3,0) -> 23.776404 | V3: =IF(U3<=L3,U3,L3) -> 23.776404
A4: CARLOS PROAÑO | B4: ZAMBRANO ZAMBRANO CLEYTON ELIECER | C4: AUTOSERVICIO INDEPENDIENTE | D4: CREMA | E4: =_xlfn.CONCAT(B4,D4) -> ZAMBRANO ZAMBRANO CLEYTON ELIECERCREMA | F4: 1314 | G4: 1314 | H4: 1314 | I4: =+F4+G4+H4 -> 3942 | J4: 0.035 | K4: =+I4*J4 -> 137.97 | L4: =(I4*1.1)*J4 -> 151.767 | M4: 1401.5472 | N4: 1074.4788 | O4: 1923.408 | P4: 0 | Q4: =SUM(M4:O4) -> 4399.434 | R4: =+Q4/I4 -> 1.1160411 | S4: =IF(R4>=80%,"GANA","NO GANA") -> GANA | T4: =VLOOKUP(B4,'CUOTA TOTAL'!$B$4:$F$72,5,FALSE) -> GANA | U4: =IF(AND(T4="GANA",S4="GANA"),Q4*J4,0) -> 153.98019 | V4: =IF(U4<=L4,U4,L4) -> 151.767
A5: CARLOS PROAÑO | B5: ZAMBRANO ZAMBRANO CLEYTON ELIECER | C5: AUTOSERVICIO INDEPENDIENTE | D5: LIQUIDO | E5: ZAMBRANO ZAMBRANO CLEYTON ELIECERLIQUIDO | F5: 110 | G5: 110 | H5: 110 | I5: =+F5+G5+H5 -> 330 | J5: 0.015 | K5: =+I5*J5 -> 4.95 | L5: =(I5*1.1)*J5 -> 5.445 | M5: 404.3616 | N5: 0 | O5: 0 | P5: 0 | Q5: =SUM(M5:O5) -> 404.3616 | R5: =+Q5/I5 -> 1.2253382 | S5: =IF(R5>=80%,"GANA","NO GANA") -> GANA | T5: =VLOOKUP(B5,'CUOTA TOTAL'!$B$4:$F$72,5,FALSE) -> GANA | U5: =IF(AND(T5="GANA",S5="GANA"),Q5*J5,0) -> 6.065424 | V5: =IF(U5<=L5,U5,L5) -> 5.445
A6: CARLOS PROAÑO | B6: ZAMBRANO ZAMBRANO CLEYTON ELIECER | C6: AUTOSERVICIO INDEPENDIENTE | D6: POLVO DETERGENTE | E6: =_xlfn.CONCAT(B6,D6) -> ZAMBRANO ZAMBRANO CLEYTON ELIECERPOLVO DETERGENTE | F6: 1650 | G6: 1650 | H6: 1650 | I6: =+F6+G6+H6 -> 4950 | J6: 0.045 | K6: =+I6*J6 -> 222.75 | L6: =(I6*1.1)*J6 -> 245.025 | M6: 1770.597 | N6: 1180.792 | O6: 2367.816 | P6: 0 | Q6: =SUM(M6:O6) -> 5319.205 | R6: =+Q6/I6 -> 1.0745869 | S6: =IF(R6>=80%,"GANA","NO GANA") -> GANA | T6: =VLOOKUP(B6,'CUOTA TOTAL'!$B$4:$F$72,5,FALSE) -> GANA | U6: =IF(AND(T6="GANA",S6="GANA"),Q6*J6,0) -> 239.36423 | V6: =IF(U6<=L6,U6,L6) -> 239.36423
A7: CARLOS PROAÑO | B7: ZAMBRANO ZAMBRANO CLEYTON ELIECER | C7: AUTOSERVICIO INDEPENDIENTE | D7: OTRAS CATEGORIAS | E7: =_xlfn.CONCAT(B7,D7) -> ZAMBRANO ZAMBRANO CLEYTON ELIECEROTRAS CATEGORIAS | F7: 10 | G7: 10 | H7: 10 | I7: =+F7+G7+H7 -> 30 | K7: =+I7*J7 -> 0 | L7: =(I7*1.1)*J7 -> 0 | M7: 79 | O7: 39 | P7: 0 | Q7: =SUM(M7:O7) -> 118 | R7: =+Q7/I7 -> 3.9333333 | S7: =IF(R7>=80%,"GANA","NO GANA") -> GANA | T7: =VLOOKUP(B7,'CUOTA TOTAL'!$B$4:$F$72,5,FALSE) -> GANA | U7: =IF(AND(T7="GANA",S7="GANA"),Q7*J7,0) -> 0 | V7: =IF(U7<=L7,U7,L7) -> 0
A8: CARLOS PROAÑO | B8: ZAMBRANO VALENCIA MARGARITA | C8: AUTOSERVICIO INDEPENDIENTE | D8: BARRA | E8: =_xlfn.CONCAT(B8,D8) -> ZAMBRANO VALENCIA MARGARITABARRA | F8: 2152.88 | G8: 2152.88 | H8: 2152.88 | I8: =+F8+G8+H8 -> 6458.64 | J8: 0.015 | K8: =+I8*J8 -> 96.8796 | L8: =(I8*1.1)*J8 -> 106.56756 | M8: 0 | N8: 5250.5104 | O8: 0 | P8: 0 | Q8: =SUM(M8:O8) -> 5250.5104 | R8: =+Q8/I8 -> 0.81294365 | S8: =IF(R8>=80%,"GANA","NO GANA") -> GANA | T8: =VLOOKUP(B8,'CUOTA TOTAL'!$B$4:$F$72,5,FALSE) -> NO GANA | U8: =IF(AND(T8="GANA",S8="GANA"),Q8*J8,0) -> 0 | V8: =IF(U8<=L8,U8,L8) -> 0
A9: CARLOS PROAÑO | B9: ZAMBRANO VALENCIA MARGARITA | C9: AUTOSERVICIO INDEPENDIENTE | D9: CREMA | E9: =_xlfn.CONCAT(B9,D9) -> ZAMBRANO VALENCIA MARGARITACREMA | F9: 2051 | G9: 2051 | H9: 2051 | I9: =+F9+G9+H9 -> 6153 | J9: 0.035 | K9: =+I9*J9 -> 215.355 | L9: =(I9*1.1)*J9 -> 236.8905 | M9: 0 | N9: 1473.0102 | O9: 0 | P9: 0 | Q9: =SUM(M9:O9) -> 1473.0102 | R9: =+Q9/I9 -> 0.23939707 | S9: =IF(R9>=80%,"GANA","NO GANA") -> NO GANA | T9: =VLOOKUP(B9,'CUOTA TOTAL'!$B$4:$F$72,5,FALSE) -> NO GANA | U9: =IF(AND(T9="GANA",S9="GANA"),Q9*J9,0) -> 0 | V9: =IF(U9<=L9,U9,L9) -> 0
A10: CARLOS PROAÑO | B10: ZAMBRANO VALENCIA MARGARITA | C10: AUTOSERVICIO INDEPENDIENTE | D10: LIQUIDO | E10: =_xlfn.CONCAT(B10,D10) -> ZAMBRANO VALENCIA MARGARITALIQUIDO | F10: 643 | G10: 643 | H10: 643 | I10: =+F10+G10+H10 -> 1929 | J10: 0.015 | K10: =+I10*J10 -> 28.935 | L10: =(I10*1.1)*J10 -> 31.8285 | M10: 0 | N10: 561.0848 | O10: 0 | P10: 0 | Q10: =SUM(M10:O10) -> 561.0848 | R10: =+Q10/I10 -> 0.29086822 | S10: =IF(R10>=80%,"GANA","NO GANA") -> NO GANA | T10: =VLOOKUP(B10,'CUOTA TOTAL'!$B$4:$F$72,5,FALSE) -> NO GANA | U10: =IF(AND(T10="GANA",S10="GANA"),Q10*J10,0) -> 0 | V10: =IF(U10<=L10,U10,L10) -> 0
A11: CARLOS PROAÑO | B11: ZAMBRANO VALENCIA MARGARITA | C11: AUTOSERVICIO INDEPENDIENTE | D11: POLVO DETERGENTE | E11: =_xlfn.CONCAT(B11,D11) -> ZAMBRANO VALENCIA MARGARITAPOLVO DETERGENTE | F11: 3480 | G11: 3480 | H11: 3480 | I11: =+F11+G11+H11 -> 10440 | J11: 0.045 | K11: =+I11*J11 -> 469.8 | L11: =(I11*1.1)*J11 -> 516.78 | M11: 0 | N11: 2638.0384 | O11: 0 | P11: 0 | Q11: =SUM(M11:O11) -> 2638.0384 | R11: =+Q11/I11 -> 0.25268567 | S11: =IF(R11>=80%,"GANA","NO GANA") -> NO GANA | T11: =VLOOKUP(B11,'CUOTA TOTAL'!$B$4:$F$72,5,FALSE) -> NO GANA | U11: =IF(AND(T11="GANA",S11="GANA"),Q11*J11,0) -> 0 | V11: =IF(U11<=L11,U11,L11) -> 0
A12: CARLOS PROAÑO | B12: ZAMBRANO VALENCIA MARGARITA | C12: AUTOSERVICIO INDEPENDIENTE | D12: OTRAS CATEGORIAS | E12: =_xlfn.CONCAT(B12,D12) -> ZAMBRANO VALENCIA MARGARITAOTRAS CATEGORIAS | F12: 30 | G12: 30 | H12: 30 | I12: =+F12+G12+H12 -> 90 | K12: =+I12*J12 -> 0 | L12: =(I12*1.1)*J12 -> 0 | M12: 0 | N12: 0 | O12: 0 | P12: 0 | Q12: =SUM(M12:O12) -> 0 | R12: =+Q12/I12 -> 0 | S12: =IF(R12>=80%,"GANA","NO GANA") -> NO GANA | T12: =VLOOKUP(B12,'CUOTA TOTAL'!$B$4:$F$72,5,FALSE) -> NO GANA | U12: =IF(AND(T12="GANA",S12="GANA"),Q12*J12,0) -> 0 | V12: =IF(U12<=L12,U12,L12) -> 0
A13: CARLOS PROAÑO | B13: ZAMBRANO MOLINA JORGE EDUARDO | C13: AUTOSERVICIO INDEPENDIENTE | D13: BARRA | E13: =_xlfn.CONCAT(B13,D13) -> ZAMBRANO MOLINA JORGE EDUARDOBARRA | F13: 556 | G13: 556 | H13: 556 | I13: =+F13+G13+H13 -> 1668 | J13: 0.015 | K13: =+I13*J13 -> 25.02 | L13: =(I13*1.1)*J13 -> 27.522 | M13: 518.912 | N13: 515.448 | O13: 670.198 | P13: 0 | Q13: =SUM(M13:O13) -> 1704.558 | R13: =+Q13/I13 -> 1.0219173 | S13: =IF(R13>=80%,"GANA","NO GANA") -> GANA | T13: =VLOOKUP(B13,'CUOTA TOTAL'!$B$4:$F$72,5,FALSE) -> GANA | U13: =IF(AND(T13="GANA",S13="GANA"),Q13*J13,0) -> 25.56837 | V13: =IF(U13<=L13,U13,L13) -> 25.56837
A14: CARLOS PROAÑO | B14: ZAMBRANO MOLINA JORGE EDUARDO | C14: AUTOSERVICIO INDEPENDIENTE | D14: CREMA | E14: =_xlfn.CONCAT(B14,D14) -> ZAMBRANO MOLINA JORGE EDUARDOCREMA | F14: 1315.43 | G14: 1315.43 | H14: 1315.43 | I14: =+F14+G14+H14 -> 3946.29 | J14: 0.035 | K14: =+I14*J14 -> 138.12015 | L14: =(I14*1.1)*J14 -> 151.93216 | M14: 369.4164 | N14: 2220.4902 | O14: 1741.0482 | P14: 0 | Q14: =SUM(M14:O14) -> 4330.9548 | R14: =+Q14/I14 -> 1.097475 | S14: =IF(R14>=80%,"GANA","NO GANA") -> GANA | T14: =VLOOKUP(B14,'CUOTA TOTAL'!$B$4:$F$72,5,FALSE) -> GANA | U14: =IF(AND(T14="GANA",S14="GANA"),Q14*J14,0) -> 151.58342 | V14: =IF(U14<=L14,U14,L14) -> 151.58342
A15: CARLOS PROAÑO | B15: ZAMBRANO MOLINA JORGE EDUARDO | C15: AUTOSERVICIO INDEPENDIENTE | D15: LIQUIDO | E15: =_xlfn.CONCAT(B15,D15) -> ZAMBRANO MOLINA JORGE EDUARDOLIQUIDO | F15: 430 | G15: 430 | H15: 430 | I15: =+F15+G15+H15 -> 1290 | J15: 0.015 | K15: =+I15*J15 -> 19.35 | L15: =(I15*1.1)*J15 -> 21.285 | M15: 487.08 | N15: 716.7984 | O15: 175.9632 | P15: 0 | Q15: =SUM(M15:O15) -> 1379.8416 | R15: =+Q15/I15 -> 1.0696447 | S15: =IF(R15>=80%,"GANA","NO GANA") -> GANA | T15: =VLOOKUP(B15,'CUOTA TOTAL'!$B$4:$F$72,5,FALSE) -> GANA | U15: =IF(AND(T15="GANA",S15="GANA"),Q15*J15,0) -> 20.697624 | V15: =IF(U15<=L15,U15,L15) -> 20.697624
A16: CARLOS PROAÑO | B16: ZAMBRANO MOLINA JORGE EDUARDO | C16: AUTOSERVICIO INDEPENDIENTE | D16: POLVO DETERGENTE | E16: =_xlfn.CONCAT(B16,D16) -> ZAMBRANO MOLINA JORGE EDUARDOPOLVO DETERGENTE | F16: 1112 | G16: 1112 | H16: 1112 | I16: =+F16+G16+H16 -> 3336 | J16: 0.045 | K16: =+I16*J16 -> 150.12 | L16: =(I16*1.1)*J16 -> 165.132 | M16: 0 | N16: 984.236 | O16: 2344.4312 | P16: 0 | Q16: =SUM(M16:O16) -> 3328.6672 | R16: =+Q16/I16 -> 0.99780192 | S16: =IF(R16>=80%,"GANA","NO GANA") -> GANA | T16: =VLOOKUP(B16,'CUOTA TOTAL'!$B$4:$F$72,5,FALSE) -> GANA | U16: =IF(AND(T16="GANA",S16="GANA"),Q16*J16,0) -> 149.79002 | V16: =IF(U16<=L16,U16,L16) -> 149.79002
A17: CARLOS PROAÑO | B17: ZAMBRANO MOLINA JORGE EDUARDO | C17: AUTOSERVICIO INDEPENDIENTE | D17: OTRAS CATEGORIAS | E17: =_xlfn.CONCAT(B17,D17) -> ZAMBRANO MOLINA JORGE EDUARDOOTRAS CATEGORIAS | F17: 10 | G17: 10 | H17: 10 | I17: =+F17+G17+H17 -> 30 | K17: =+I17*J17 -> 0 | L17: =(I17*1.1)*J17 -> 0 | O17: 12 | P17: 0 | Q17: =SUM(M17:O17) -> 12 | R17: =+Q17/I17 -> 0.4 | S17: =IF(R17>=80%,"GANA","NO GANA") -> NO GANA | T17: =VLOOKUP(B17,'CUOTA TOTAL'!$B$4:$F$72,5,FALSE) -> GANA | U17: =IF(AND(T17="GANA",S17="GANA"),Q17*J17,0) -> 0 | V17: =IF(U17<=L17,U17,L17) -> 0
A18: CARLOS PROAÑO | B18: ZAMBRANO MACIAS FRANCISCO GREGORIO | C18: AUTOSERVICIO INDEPENDIENTE | D18: BARRA | E18: =_xlfn.CONCAT(B18,D18) -> ZAMBRANO MACIAS FRANCISCO GREGORIOBARRA | F18: 1500 | G18: 1500 | H18: 1500 | I18: =+F18+G18+H18 -> 4500 | J18: 0.015 | K18: =+I18*J18 -> 67.5 | L18: =(I18*1.1)*J18 -> 74.25 | M18: 280.8 | N18: 1261.5296 | O18: 3486.2112 | P18: 0 | Q18: =SUM(M18:O18) -> 5028.5408 | R18: =+Q18/I18 -> 1.1174535 | S18: =IF(R18>=80%,"GANA","NO GANA") -> GANA | T18: =VLOOKUP(B18,'CUOTA TOTAL'!$B$4:$F$72,5,FALSE) -> GANA | U18: =IF(AND(T18="GANA",S18="GANA"),Q18*J18,0) -> 75.428112 | V18: =IF(U18<=L18,U18,L18) -> 74.25
A19: CARLOS PROAÑO | B19: ZAMBRANO MACIAS FRANCISCO GREGORIO | C19: AUTOSERVICIO INDEPENDIENTE | D19: CREMA | E19: =_xlfn.CONCAT(B19,D19) -> ZAMBRANO MACIAS FRANCISCO GREGORIOCREMA | F19: 2497.64 | G19: 2497.64 | H19: 2497.64 | I19: =+F19+G19+H19 -> 7492.92 | J19: 0.035 | K19: =+I19*J19 -> 262.2522 | L19: =(I19*1.1)*J19 -> 288.47742 | M19: 0 | N19: 2807.5824 | O19: 4784.3952 | P19: 0 | Q19: =SUM(M19:O19) -> 7591.9776 | R19: =+Q19/I19 -> 1.0132202 | S19: =IF(R19>=80%,"GANA","NO GANA") -> GANA | T19: =VLOOKUP(B19,'CUOTA TOTAL'!$B$4:$F$72,5,FALSE) -> GANA | U19: =IF(AND(T19="GANA",S19="GANA"),Q19*J19,0) -> 265.71922 | V19: =IF(U19<=L19,U19,L19) -> 265.71922
A20: CARLOS PROAÑO | B20: ZAMBRANO MACIAS FRANCISCO GREGORIO | C20: AUTOSERVICIO INDEPENDIENTE | D20: LIQUIDO | E20: =_xlfn.CONCAT(B20,D20) -> ZAMBRANO MACIAS FRANCISCO GREGORIOLIQUIDO | F20: 442 | G20: 442 | H20: 442 | I20: =+F20+G20+H20 -> 1326 | J20: 0.015 | K20: =+I20*J20 -> 19.89 | L20: =(I20*1.1)*J20 -> 21.879 | M20: 0 | N20: 478.875 | O20: 476.3982 | P20: 0 | Q20: =SUM(M20:O20) -> 955.2732 | R20: =+Q20/I20 -> 0.72041719 | S20: =IF(R20>=80%,"GANA","NO GANA") -> NO GANA | T20: =VLOOKUP(B20,'CUOTA TOTAL'!$B$4:$F$72,5,FALSE) -> GANA | U20: =IF(AND(T20="GANA",S20="GANA"),Q20*J20,0) -> 0 | V20: =IF(U20<=L20,U20,L20) -> 0
A21: CARLOS PROAÑO | B21: ZAMBRANO MACIAS FRANCISCO GREGORIO | C21: AUTOSERVICIO INDEPENDIENTE | D21: POLVO DETERGENTE | E21: =_xlfn.CONCAT(B21,D21) -> ZAMBRANO MACIAS FRANCISCO GREGORIOPOLVO DETERGENTE | F21: 4700 | G21: 4700 | H21: 4700 | I21: =+F21+G21+H21 -> 14100 | J21: 0.045 | K21: =+I21*J21 -> 634.5 | L21: =(I21*1.1)*J21 -> 697.95 | M21: 0 | N21: 4295.472 | O21: 9994.52 | P21: 0 | Q21: =SUM(M21:O21) -> 14289.992 | R21: =+Q21/I21 -> 1.0134746 | S21: =IF(R21>=80%,"GANA","NO GANA") -> GANA | T21: =VLOOKUP(B21,'CUOTA TOTAL'!$B$4:$F$72,5,FALSE) -> GANA | U21: =IF(AND(T21="GANA",S21="GANA"),Q21*J21,0) -> 643.04964 | V21: =IF(U21<=L21,U21,L21) -> 643.04964
A22: CARLOS PROAÑO | B22: ZAMBRANO MACIAS FRANCISCO GREGORIO | C22: AUTOSERVICIO INDEPENDIENTE | D22: OTRAS CATEGORIAS | E22: =_xlfn.CONCAT(B22,D22) -> ZAMBRANO MACIAS FRANCISCO GREGORIOOTRAS CATEGORIAS | F22: 20 | G22: 20 | H22: 20 | I22: =+F22+G22+H22 -> 60 | K22: =+I22*J22 -> 0 | L22: =(I22*1.1)*J22 -> 0 | M22: 0 | N22: 0 | O22: 0 | P22: 0 | Q22: =SUM(M22:O22) -> 0 | R22: =+Q22/I22 -> 0 | S22: =IF(R22>=80%,"GANA","NO GANA") -> NO GANA | T22: =VLOOKUP(B22,'CUOTA TOTAL'!$B$4:$F$72,5,FALSE) -> GANA | U22: =IF(AND(T22="GANA",S22="GANA"),Q22*J22,0) -> 0 | V22: =IF(U22<=L22,U22,L22) -> 0
A23: JAVIER MALDONADO | B23: YUCAILLA PADILLA RENE WILFRIDO | C23: AUTOSERVICIO INDEPENDIENTE | D23: BARRA | E23: =_xlfn.CONCAT(B23,D23) -> YUCAILLA PADILLA RENE WILFRIDOBARRA | F23: 15 | G23: 15 | H23: 15 | I23: =+F23+G23+H23 -> 45 | J23: 0.015 | K23: =+I23*J23 -> 0.675 | L23: =(I23*1.1)*J23 -> 0.7425 | M23: 0 | N23: 0 | O23: 0 | P23: 0 | Q23: =SUM(M23:O23) -> 0 | R23: =+Q23/I23 -> 0 | S23: =IF(R23>=80%,"GANA","NO GANA") -> NO GANA | T23: =VLOOKUP(B23,'CUOTA TOTAL'!$B$4:$F$72,5,FALSE) -> GANA | U23: =IF(AND(T23="GANA",S23="GANA"),Q23*J23,0) -> 0 | V23: =IF(U23<=L23,U23,L23) -> 0
A24: JAVIER MALDONADO | B24: YUCAILLA PADILLA RENE WILFRIDO | C24: AUTOSERVICIO INDEPENDIENTE | D24: CREMA | E24: =_xlfn.CONCAT(B24,D24) -> YUCAILLA PADILLA RENE WILFRIDOCREMA | F24: 1611 | G24: 1611 | H24: 1611 | I24: =+F24+G24+H24 -> 4833 | J24: 0.04 | K24: =+I24*J24 -> 193.32 | L24: =(I24*1.1)*J24 -> 212.652 | M24: 0 | N24: 0 | O24: 5238.8112 | P24: 0 | Q24: =SUM(M24:O24) -> 5238.8112 | R24: =+Q24/I24 -> 1.0839667 | S24: =IF(R24>=80%,"GANA","NO GANA") -> GANA | T24: =VLOOKUP(B24,'CUOTA TOTAL'!$B$4:$F$72,5,FALSE) -> GANA | U24: =IF(AND(T24="GANA",S24="GANA"),Q24*J24,0) -> 209.55245 | V24: =IF(U24<=L24,U24,L24) -> 209.55245
A25: JAVIER MALDONADO | B25: YUCAILLA PADILLA RENE WILFRIDO | C25: AUTOSERVICIO INDEPENDIENTE | D25: LIQUIDO | E25: =_xlfn.CONCAT(B25,D25) -> YUCAILLA PADILLA RENE WILFRIDOLIQUIDO | F25: 15 | G25: 15 | H25: 15 | I25: =+F25+G25+H25 -> 45 | J25: 0.015 | K25: =+I25*J25 -> 0.675 | L25: =(I25*1.1)*J25 -> 0.7425 | M25: 0 | N25: 0 | O25: 259.776 | P25: 0 | Q25: =SUM(M25:O25) -> 259.776 | R25: =+Q25/I25 -> 5.7728 | S25: =IF(R25>=80%,"GANA","NO GANA") -> GANA | T25: =VLOOKUP(B25,'CUOTA TOTAL'!$B$4:$F$72,5,FALSE) -> GANA | U25: =IF(AND(T25="GANA",S25="GANA"),Q25*J25,0) -> 3.89664 | V25: =IF(U25<=L25,U25,L25) -> 0.7425
A26: JAVIER MALDONADO | B26: YUCAILLA PADILLA RENE WILFRIDO | C26: AUTOSERVICIO INDEPENDIENTE | D26: POLVO DETERGENTE | E26: =_xlfn.CONCAT(B26,D26) -> YUCAILLA PADILLA RENE WILFRIDOPOLVO DETERGENTE | F26: 427 | G26: 427 | H26: 427 | I26: =+F26+G26+H26 -> 1281 | J26: 0.04 | K26: =+I26*J26 -> 51.24 | L26: =(I26*1.1)*J26 -> 56.364 | M26: 0 | N26: 0 | O26: 1674.0864 | P26: 0 | Q26: =SUM(M26:O26) -> 1674.0864 | R26: =+Q26/I26 -> 1.306859 | S26: =IF(R26>=80%,"GANA","NO GANA") -> GANA | T26: =VLOOKUP(B26,'CUOTA TOTAL'!$B$4:$F$72,5,FALSE) -> GANA | U26: =IF(AND(T26="GANA",S26="GANA"),Q26*J26,0) -> 66.963456 | V26: =IF(U26<=L26,U26,L26) -> 56.364
A27: JAVIER MALDONADO | B27: YUCAILLA PADILLA RENE WILFRIDO | C27: AUTOSERVICIO INDEPENDIENTE | D27: OTRAS CATEGORIAS | E27: =_xlfn.CONCAT(B27,D27) -> YUCAILLA PADILLA RENE WILFRIDOOTRAS CATEGORIAS | I27: =+F27+G27+H27 -> 0 | K27: =+I27*J27 -> 0 | L27: =(I27*1.1)*J27 -> 0 | M27: 0 | N27: 0 | O27: 0 | P27: 0 | Q27: =SUM(M27:O27) -> 0 | R27: 0 | S27: =IF(R27>=80%,"GANA","NO GANA") -> NO GANA | T27: =VLOOKUP(B27,'CUOTA TOTAL'!$B$4:$F$72,5,FALSE) -> GANA | U27: =IF(AND(T27="GANA",S27="GANA"),Q27*J27,0) -> 0 | V27: =IF(U27<=L27,U27,L27) -> 0
A28: XAVIER ALVARADO | B28: YANEZ CARDENAS ESTELA ELIZABETH | C28: MAYORISTA PURO | D28: BARRA | E28: =_xlfn.CONCAT(B28,D28) -> YANEZ CARDENAS ESTELA ELIZABETHBARRA | F28: 3585 | G28: 3585 | H28: 3585 | I28: =+F28+G28+H28 -> 10755 | J28: 0.015 | K28: =+I28*J28 -> 161.325 | L28: =(I28*1.1)*J28 -> 177.4575 | M28: 1196.4288 | N28: 0 | O28: 0 | P28: 0 | Q28: =SUM(M28:O28) -> 1196.4288 | R28: =+Q28/I28 -> 0.11124396 | S28: =IF(R28>=80%,"GANA","NO GANA") -> NO GANA | T28: =VLOOKUP(B28,'CUOTA TOTAL'!$B$4:$F$72,5,FALSE) -> GANA | U28: =IF(AND(T28="GANA",S28="GANA"),Q28*J28,0) -> 0 | V28: =IF(U28<=L28,U28,L28) -> 0
A29: XAVIER ALVARADO | B29: YANEZ CARDENAS ESTELA ELIZABETH | C29: MAYORISTA PURO | D29: CREMA | E29: =_xlfn.CONCAT(B29,D29) -> YANEZ CARDENAS ESTELA ELIZABETHCREMA | F29: 637 | G29: 637 | H29: 637 | I29: =+F29+G29+H29 -> 1911 | J29: 0.015 | K29: =+I29*J29 -> 28.665 | L29: =(I29*1.1)*J29 -> 31.5315 | M29: 0 | N29: 0 | O29: 0 | P29: 0 | Q29: =SUM(M29:O29) -> 0 | R29: =+Q29/I29 -> 0 | S29: =IF(R29>=80%,"GANA","NO GANA") -> NO GANA | T29: =VLOOKUP(B29,'CUOTA TOTAL'!$B$4:$F$72,5,FALSE) -> GANA | U29: =IF(AND(T29="GANA",S29="GANA"),Q29*J29,0) -> 0 | V29: =IF(U29<=L29,U29,L29) -> 0
A30: XAVIER ALVARADO | B30: YANEZ CARDENAS ESTELA ELIZABETH | C30: MAYORISTA PURO | D30: LIQUIDO | E30: =_xlfn.CONCAT(B30,D30) -> YANEZ CARDENAS ESTELA ELIZABETHLIQUIDO | F30: 500 | G30: 500 | H30: 500 | I30: =+F30+G30+H30 -> 1500 | J30: 0.015 | K30: =+I30*J30 -> 22.5 | L30: =(I30*1.1)*J30 -> 24.75 | M30: 0 | N30: 0 | O30: 0 | P30: 0 | Q30: =SUM(M30:O30) -> 0 | R30: =+Q30/I30 -> 0 | S30: =IF(R30>=80%,"GANA","NO GANA") -> NO GANA | T30: =VLOOKUP(B30,'CUOTA TOTAL'!$B$4:$F$72,5,FALSE) -> GANA | U30: =IF(AND(T30="GANA",S30="GANA"),Q30*J30,0) -> 0 | V30: =IF(U30<=L30,U30,L30) -> 0
A31: XAVIER ALVARADO | B31: YANEZ CARDENAS ESTELA ELIZABETH | C31: MAYORISTA PURO | D31: POLVO DETERGENTE | E31: =_xlfn.CONCAT(B31,D31) -> YANEZ CARDENAS ESTELA ELIZABETHPOLVO DETERGENTE | F31: 5493 | G31: 5493 | H31: 5493 | I31: =+F31+G31+H31 -> 16479 | J31: 0.015 | K31: =+I31*J31 -> 247.185 | L31: =(I31*1.1)*J31 -> 271.9035 | M31: 8161.1712 | N31: 0 | O31: 26157.6 | P31: 0 | Q31: =SUM(M31:O31) -> 34318.771 | R31: =+Q31/I31 -> 2.0825761 | S31: =IF(R31>=80%,"GANA","NO GANA") -> GANA | T31: =VLOOKUP(B31,'CUOTA TOTAL'!$B$4:$F$72,5,FALSE) -> GANA | U31: =IF(AND(T31="GANA",S31="GANA"),Q31*J31,0) -> 514.78157 | V31: =IF(U31<=L31,U31,L31) -> 271.9035
A32: XAVIER ALVARADO | B32: YANEZ CARDENAS ESTELA ELIZABETH | C32: MAYORISTA PURO | D32: OTRAS CATEGORIAS | E32: =_xlfn.CONCAT(B32,D32) -> YANEZ CARDENAS ESTELA ELIZABETHOTRAS CATEGORIAS | F32: 60 | G32: 60 | H32: 60 | I32: =+F32+G32+H32 -> 180 | J32: 0.015 | K32: =+I32*J32 -> 2.7 | L32: =(I32*1.1)*J32 -> 2.97 | M32: 0 | N32: 0 | O32: 0 | P32: 0 | Q32: =SUM(M32:O32) -> 0 | R32: =+Q32/I32 -> 0 | S32: =IF(R32>=80%,"GANA","NO GANA") -> NO GANA | T32: =VLOOKUP(B32,'CUOTA TOTAL'!$B$4:$F$72,5,FALSE) -> GANA | U32: =IF(AND(T32="GANA",S32="GANA"),Q32*J32,0) -> 0 | V32: =IF(U32<=L32,U32,L32) -> 0
A33: XAVIER ALVARADO | B33: YAGUACHI QUISHPI MARIA ELVIRA | C33: MAYORISTA PURO | D33: BARRA | E33: =_xlfn.CONCAT(B33,D33) -> YAGUACHI QUISHPI MARIA ELVIRABARRA | F33: 4600 | G33: 4600 | H33: 4600 | I33: =+F33+G33+H33 -> 13800 | J33: 0.015 | K33: =+I33*J33 -> 207 | L33: =(I33*1.1)*J33 -> 227.7 | M33: 0 | N33: 3556.8 | O33: 0 | P33: 0 | Q33: =SUM(M33:O33) -> 3556.8 | R33: =+Q33/I33 -> 0.25773913 | S33: =IF(R33>=80%,"GANA","NO GANA") -> NO GANA | T33: =VLOOKUP(B33,'CUOTA TOTAL'!$B$4:$F$72,5,FALSE) -> NO GANA | U33: =IF(AND(T33="GANA",S33="GANA"),Q33*J33,0) -> 0 | V33: =IF(U33<=L33,U33,L33) -> 0
A34: XAVIER ALVARADO | B34: YAGUACHI QUISHPI MARIA ELVIRA | C34: MAYORISTA PURO | D34: CREMA | E34: =_xlfn.CONCAT(B34,D34) -> YAGUACHI QUISHPI MARIA ELVIRACREMA | F34: 1025 | G34: 1025 | H34: 1025 | I34: =+F34+G34+H34 -> 3075 | J34: 0.015 | K34: =+I34*J34 -> 46.125 | L34: =(I34*1.1)*J34 -> 50.7375 | M34: 0 | N34: 433.92 | O34: 0 | P34: 0 | Q34: =SUM(M34:O34) -> 433.92 | R34: =+Q34/I34 -> 0.1411122 | S34: =IF(R34>=80%,"GANA","NO GANA") -> NO GANA | T34: =VLOOKUP(B34,'CUOTA TOTAL'!$B$4:$F$72,5,FALSE) -> NO GANA | U34: =IF(AND(T34="GANA",S34="GANA"),Q34*J34,0) -> 0 | V34: =IF(U34<=L34,U34,L34) -> 0
A35: XAVIER ALVARADO | B35: YAGUACHI QUISHPI MARIA ELVIRA | C35: MAYORISTA PURO | D35: LIQUIDO | E35: =_xlfn.CONCAT(B35,D35) -> YAGUACHI QUISHPI MARIA ELVIRALIQUIDO | F35: 250 | G35: 250 | H35: 250 | I35: =+F35+G35+H35 -> 750 | J35: 0.015 | K35: =+I35*J35 -> 11.25 | L35: =(I35*1.1)*J35 -> 12.375 | M35: 0 | N35: 0 | O35: 0 | P35: 0 | Q35: =SUM(M35:O35) -> 0 | R35: =+Q35/I35 -> 0 | S35: =IF(R35>=80%,"GANA","NO GANA") -> NO GANA | T35: =VLOOKUP(B35,'CUOTA TOTAL'!$B$4:$F$72,5,FALSE) -> NO GANA | U35: =IF(AND(T35="GANA",S35="GANA"),Q35*J35,0) -> 0 | V35: =IF(U35<=L35,U35,L35) -> 0
A36: XAVIER ALVARADO | B36: YAGUACHI QUISHPI MARIA ELVIRA | C36: MAYORISTA PURO | D36: POLVO DETERGENTE | E36: =_xlfn.CONCAT(B36,D36) -> YAGUACHI QUISHPI MARIA ELVIRAPOLVO DETERGENTE | F36: 6400 | G36: 6400 | H36: 6400 | I36: =+F36+G36+H36 -> 19200 | J36: 0.015 | K36: =+I36*J36 -> 288 | L36: =(I36*1.1)*J36 -> 316.8 | M36: 0 | N36: 11180.817 | O36: 0 | P36: 0 | Q36: =SUM(M36:O36) -> 11180.817 | R36: =+Q36/I36 -> 0.58233421 | S36: =IF(R36>=80%,"GANA","NO GANA") -> NO GANA | T36: =VLOOKUP(B36,'CUOTA TOTAL'!$B$4:$F$72,5,FALSE) -> NO GANA | U36: =IF(AND(T36="GANA",S36="GANA"),Q36*J36,0) -> 0 | V36: =IF(U36<=L36,U36,L36) -> 0
A37: XAVIER ALVARADO | B37: YAGUACHI QUISHPI MARIA ELVIRA | C37: MAYORISTA PURO | D37: OTRAS CATEGORIAS | E37: =_xlfn.CONCAT(B37,D37) -> YAGUACHI QUISHPI MARIA ELVIRAOTRAS CATEGORIAS | F37: 60 | G37: 60 | H37: 60 | I37: =+F37+G37+H37 -> 180 | J37: 0.015 | K37: =+I37*J37 -> 2.7 | L37: =(I37*1.1)*J37 -> 2.97 | M37: 0 | N37: 0 | O37: 0 | P37: 0 | Q37: =SUM(M37:O37) -> 0 | R37: =+Q37/I37 -> 0 | S37: =IF(R37>=80%,"GANA","NO GANA") -> NO GANA | T37: =VLOOKUP(B37,'CUOTA TOTAL'!$B$4:$F$72,5,FALSE) -> NO GANA | U37: =IF(AND(T37="GANA",S37="GANA"),Q37*J37,0) -> 0 | V37: =IF(U37<=L37,U37,L37) -> 0
A38: CARLOS PROAÑO | B38: WANG CHONG LONG | C38: AUTOSERVICIO INDEPENDIENTE | D38: BARRA | E38: =_xlfn.CONCAT(B38,D38) -> WANG CHONG LONGBARRA | F38: 953.36 | G38: 953.36 | H38: 953.36 | I38: =+F38+G38+H38 -> 2860.08 | J38: 0.015 | K38: =+I38*J38 -> 42.9012 | L38: =(I38*1.1)*J38 -> 47.19132 | M38: 0 | N38: 0 | O38: 0 | P38: 0 | Q38: =SUM(M38:O38) -> 0 | R38: =+Q38/I38 -> 0 | S38: =IF(R38>=80%,"GANA","NO GANA") -> NO GANA | T38: =VLOOKUP(B38,'CUOTA TOTAL'!$B$4:$F$72,5,FALSE) -> NO GANA | U38: =IF(AND(T38="GANA",S38="GANA"),Q38*J38,0) -> 0 | V38: =IF(U38<=L38,U38,L38) -> 0
A39: CARLOS PROAÑO | B39: WANG CHONG LONG | C39: AUTOSERVICIO INDEPENDIENTE | D39: CREMA | E39: =_xlfn.CONCAT(B39,D39) -> WANG CHONG LONGCREMA | F39: 1632.34 | G39: 1632.34 | H39: 1632.34 | I39: =+F39+G39+H39 -> 4897.02 | J39: 0.035 | K39: =+I39*J39 -> 171.3957 | L39: =(I39*1.1)*J39 -> 188.53527 | M39: 2462.1888 | N39: 1457.1792 | O39: 0 | P39: 0 | Q39: =SUM(M39:O39) -> 3919.368 | R39: =+Q39/I39 -> 0.80035777 | S39: =IF(R39>=80%,"GANA","NO GANA") -> GANA | T39: =VLOOKUP(B39,'CUOTA TOTAL'!$B$4:$F$72,5,FALSE) -> NO GANA | U39: =IF(AND(T39="GANA",S39="GANA"),Q39*J39,0) -> 0 | V39: =IF(U39<=L39,U39,L39) -> 0
... A41: CARLOS PROAÑO | B41: WANG CHONG LONG | C41: AUTOSERVICIO INDEPENDIENTE | D41: POLVO DETERGENTE | E41: =_xlfn.CONCAT(B41,D41) -> WANG CHONG LONGPOLVO DETERGENTE | F41: 1764.94 | G41: 1764.94 | H41: 1764.94 | I41: =+F41+G41+H41 -> 5294.82 | J41: 0.045 | K41: =+I41*J41 -> 238.2669 | L41: =(I41*1.1)*J41 -> 262.09359 | M41: 0 | N41: 2838.256 | O41: 0 | P41: 0 | Q41: =SUM(M41:O41) -> 2838.256 | R41: =+Q41/I41 -> 0.53604391 | S41: =IF(R41>=80%,"GANA","NO GANA") -> NO GANA | T41: =VLOOKUP(B41,'CUOTA TOTAL'!$B$4:$F$72,5,FALSE) -> NO GANA | U41: =IF(AND(T41="GANA",S41="GANA"),Q41*J41,0) -> 0 | V41: =IF(U41<=L41,U41,L41) -> 0
...
